<mujoco>
    <include file="../scene/basic_scene.xml"/>
    <include file="../objects/assets/thermos_dependencies.xml"/>
    <include file="../objects/assets/hammer_dependencies.xml"/>
    <include file="../objects/assets/xyz_base_dependencies.xml"/>

    <worldbody>
      <include file="../objects/assets/xyz_base.xml"/>

      <body name="stick" pos="0 0.6 0.02" euler="0 0 0">
        <freejoint/>
          <include file="../objects/assets/my_hammer.xml"/>
      </body>
      <body name="obj1" pos="0.21 0.7 0.1" >
            <inertial pos="0 0 0" mass="1" diaginertia="1 1 1"/>
            <joint type="slide" range="-0.2 0.2" axis="1 0 0" name="obj_slidex1" damping=".1" limited="true"/>
            <joint type="slide" range="-0.2 0.2" axis="0 1 0" name="obj_slidey1" damping=".1" limited="true"/>
            <geom type="cylinder" pos="0 0 0" size="0.02 0.1" rgba="1 0.9 1 1"/>
      </body>
      <body name="obj2" pos="0.17 0.7 0.1" >
            <inertial pos="0 0 0" mass="1" diaginertia="1 1 1"/>
            <joint type="slide" range="-0.2 0.2" axis="1 0 0" name="obj_slidex2" damping=".1" limited="true"/>
            <joint type="slide" range="-0.2 0.2" axis="0 1 0" name="obj_slidey2" damping=".1" limited="true"/>
            <geom type="cylinder" pos="0 0 0" size="0.02 0.1" rgba="1 0.5 1 1"/>
      </body>

      <body name="obj3" pos="0.13 0.7 0.1" >
            <inertial pos="0 0 0" mass="1" diaginertia="1 1 1"/>
            <joint type="slide" range="-0.2 0.2" axis="1 0 0" name="obj_slidex3" damping=".1" limited="true"/>
            <joint type="slide" range="-0.2 0.2" axis="0 1 0" name="obj_slidey3" damping=".1" limited="true"/>
            <geom type="cylinder" pos="0 0 0" size="0.02 0.1" rgba="1 0.3 1 1"/>
      </body>

      <body name="obj4" pos="0.09 0.7 0.1" >
            <inertial pos="0 0 0" mass="1" diaginertia="1 1 1"/>
            <joint type="slide" range="-0.2 0.2" axis="1 0 0" name="obj_slidex4" damping=".1" limited="true"/>
            <joint type="slide" range="-0.2 0.2" axis="0 1 0" name="obj_slidey4" damping=".1" limited="true"/>
            <geom type="cylinder" pos="0 0 0" size="0.02 0.1" rgba="1 0.1 1 1"/>
      </body>

      <site name="nailHead" pos="0.23 0.65 0.15" size="0.015"
            rgba="1 0 0 1"/>

      <site name="goal" pos="0.25 0.7 0.04" size="0.015"
            rgba="0 0.8 0 0"/>
    </worldbody>

    <actuator>
        <position ctrllimited="true" ctrlrange="-1 1" joint="r_close" kp="400"  user="1"/>
        <position ctrllimited="true" ctrlrange="-1 1" joint="l_close" kp="400"  user="1"/>
    </actuator>
    <equality>
        <weld body1="mocap" body2="hand" solref="0.02 1"></weld>
    </equality>
</mujoco>
