<mujoco>
    <include file="../scene/basic_scene.xml"/>
    <include file="../objects/assets/peg_block_dependencies.xml"/>
    <include file="../objects/assets/hammer_dependencies.xml"/>
    <include file="../objects/assets/xyz_base_dependencies.xml"/>

    <worldbody>
      <include file="../objects/assets/xyz_base.xml"/>

        <body name="my_hammer" pos="0 0.6 0.02">
            <inertial pos="0 0 0" mass="1" diaginertia="3 3 3"/>
          <joint type="free"/>
          <include file="../objects/assets/my_hammer.xml"/>
        </body>
        <body name="wall_hole" euler="0 0 1.57" pos="0.3 0.7 0">
            <geom type="box" pos="0 0 0.07" size=".3 .03 .1" material="table_wood"/>
            <geom type="box" pos="0 0 0.65" size=".3 .03 .35" material="table_wood"/>
            <geom type="box" pos="0.185 0 0.24" size="0.115 .03 0.075" material="table_wood"/>
            <geom type="box" pos="-0.185 0 0.24" size="0.115 .03 .075" material="table_wood"/>
        </body>

        <site name="goal" pos="0.34 0.7 0.24" size="0.01" rgba="0.8 0 0 1"/>

        <body name="reach" pos="0.39 0.7 0.15" >
            <inertial pos="0 0 0" mass="1" diaginertia="1 1 1"/>
            <joint type="slide" range="-0.2 0.2" axis="1 0 0" name="obj_slidex" damping=".1" limited="true"/>
            <joint type="slide" range="-0.2 0.2" axis="0 1 0" name="obj_slidey" damping=".1" limited="true"/>
            <geom type="cylinder" pos="0 0 0" size="0.05 0.15" rgba="1 1 1 1"/>
            <site name="push" pos="0 0 0.09" size="0.01" rgba="0.8 0.8 0.2 1"/>
        </body>


    </worldbody>

    <actuator>
        <position ctrllimited="true" ctrlrange="-1 1" joint="r_close" kp="400"  user="1"/>
        <position ctrllimited="true" ctrlrange="-1 1" joint="l_close" kp="400"  user="1"/>
    </actuator>
    <equality>
        <weld body1="mocap" body2="hand" solref="0.02 1"></weld>
    </equality>
</mujoco>
